[2024-07-21T00:32:14.447+0000] {taskinstance.py:1157} INFO - Dependencies all met for dep_context=non-requeueable deps ti=<TaskInstance: data_pipeline.process_data scheduled__2024-07-20T00:30:00+00:00 [queued]>
[2024-07-21T00:32:14.450+0000] {taskinstance.py:1157} INFO - Dependencies all met for dep_context=requeueable deps ti=<TaskInstance: data_pipeline.process_data scheduled__2024-07-20T00:30:00+00:00 [queued]>
[2024-07-21T00:32:14.450+0000] {taskinstance.py:1359} INFO - Starting attempt 2 of 2
[2024-07-21T00:32:14.454+0000] {taskinstance.py:1380} INFO - Executing <Task(BashOperator): process_data> on 2024-07-20 00:30:00+00:00
[2024-07-21T00:32:14.456+0000] {standard_task_runner.py:57} INFO - Started process 23734 to run task
[2024-07-21T00:32:14.458+0000] {standard_task_runner.py:84} INFO - Running: ['***', 'tasks', 'run', 'data_pipeline', 'process_data', 'scheduled__2024-07-20T00:30:00+00:00', '--job-id', '36', '--raw', '--subdir', 'DAGS_FOLDER/spark-jobs.py', '--cfg-path', '/tmp/tmpwhy_xy2y']
[2024-07-21T00:32:14.460+0000] {standard_task_runner.py:85} INFO - Job 36: Subtask process_data
[2024-07-21T00:32:14.482+0000] {task_command.py:415} INFO - Running <TaskInstance: data_pipeline.process_data scheduled__2024-07-20T00:30:00+00:00 [running]> on host c553c98b8e80
[2024-07-21T00:32:14.509+0000] {taskinstance.py:1660} INFO - Exporting env vars: AIRFLOW_CTX_DAG_OWNER='***' AIRFLOW_CTX_DAG_ID='data_pipeline' AIRFLOW_CTX_TASK_ID='process_data' AIRFLOW_CTX_EXECUTION_DATE='2024-07-20T00:30:00+00:00' AIRFLOW_CTX_TRY_NUMBER='2' AIRFLOW_CTX_DAG_RUN_ID='scheduled__2024-07-20T00:30:00+00:00'
[2024-07-21T00:32:14.509+0000] {subprocess.py:63} INFO - Tmp dir root location: /tmp
[2024-07-21T00:32:14.510+0000] {subprocess.py:75} INFO - Running command: ['/bin/bash', '-c', 'python /opt/***/jobs/process_data.py ']
[2024-07-21T00:32:14.513+0000] {subprocess.py:86} INFO - Output:
[2024-07-21T00:32:14.548+0000] {subprocess.py:93} INFO - python: can't open file '/opt/***/jobs/process_data.py': [Errno 2] No such file or directory
[2024-07-21T00:32:14.550+0000] {subprocess.py:97} INFO - Command exited with return code 2
[2024-07-21T00:32:14.554+0000] {taskinstance.py:1935} ERROR - Task failed with exception
Traceback (most recent call last):
  File "/home/airflow/.local/lib/python3.11/site-packages/airflow/operators/bash.py", line 210, in execute
    raise AirflowException(
airflow.exceptions.AirflowException: Bash command failed. The command returned a non-zero exit code 2.
[2024-07-21T00:32:14.555+0000] {taskinstance.py:1398} INFO - Marking task as FAILED. dag_id=data_pipeline, task_id=process_data, execution_date=20240720T003000, start_date=20240721T003214, end_date=20240721T003214
[2024-07-21T00:32:14.559+0000] {standard_task_runner.py:104} ERROR - Failed to execute job 36 for task process_data (Bash command failed. The command returned a non-zero exit code 2.; 23734)
[2024-07-21T00:32:14.597+0000] {local_task_job_runner.py:228} INFO - Task exited with return code 1
[2024-07-21T00:32:14.604+0000] {taskinstance.py:2776} INFO - 0 downstream tasks scheduled from follow-on schedule check
