[2024-08-20T00:43:12.936+0000] {taskinstance.py:1157} INFO - Dependencies all met for dep_context=non-requeueable deps ti=<TaskInstance: data_pipeline_api.fetch_data scheduled__2024-08-19T00:30:00+00:00 [queued]>
[2024-08-20T00:43:12.940+0000] {taskinstance.py:1157} INFO - Dependencies all met for dep_context=requeueable deps ti=<TaskInstance: data_pipeline_api.fetch_data scheduled__2024-08-19T00:30:00+00:00 [queued]>
[2024-08-20T00:43:12.940+0000] {taskinstance.py:1359} INFO - Starting attempt 2 of 2
[2024-08-20T00:43:12.946+0000] {taskinstance.py:1380} INFO - Executing <Task(BashOperator): fetch_data> on 2024-08-19 00:30:00+00:00
[2024-08-20T00:43:12.952+0000] {standard_task_runner.py:57} INFO - Started process 77066 to run task
[2024-08-20T00:43:12.955+0000] {standard_task_runner.py:84} INFO - Running: ['***', 'tasks', 'run', 'data_pipeline_api', 'fetch_data', 'scheduled__2024-08-19T00:30:00+00:00', '--job-id', '72', '--raw', '--subdir', 'DAGS_FOLDER/spark-jobs.py', '--cfg-path', '/tmp/tmpv5unku84']
[2024-08-20T00:43:12.961+0000] {standard_task_runner.py:85} INFO - Job 72: Subtask fetch_data
[2024-08-20T00:43:13.035+0000] {task_command.py:415} INFO - Running <TaskInstance: data_pipeline_api.fetch_data scheduled__2024-08-19T00:30:00+00:00 [running]> on host 27ef58cc88fc
[2024-08-20T00:43:13.128+0000] {taskinstance.py:1660} INFO - Exporting env vars: AIRFLOW_CTX_DAG_OWNER='***' AIRFLOW_CTX_DAG_ID='data_pipeline_api' AIRFLOW_CTX_TASK_ID='fetch_data' AIRFLOW_CTX_EXECUTION_DATE='2024-08-19T00:30:00+00:00' AIRFLOW_CTX_TRY_NUMBER='2' AIRFLOW_CTX_DAG_RUN_ID='scheduled__2024-08-19T00:30:00+00:00'
[2024-08-20T00:43:13.131+0000] {subprocess.py:63} INFO - Tmp dir root location: /tmp
[2024-08-20T00:43:13.133+0000] {subprocess.py:75} INFO - Running command: ['/bin/bash', '-c', 'bash /opt/***/jobs/spark-submit.sh /opt/***/jobs/fetch_data.py ']
[2024-08-20T00:43:13.144+0000] {subprocess.py:86} INFO - Output:
[2024-08-20T00:43:13.165+0000] {subprocess.py:93} INFO - /opt/***/jobs/fetch_data.py
[2024-08-20T00:43:13.264+0000] {subprocess.py:93} INFO - /home/***/.local/lib/python3.11/site-packages/pyspark/bin/load-spark-env.sh: line 68: ps: command not found
[2024-08-20T00:43:14.762+0000] {subprocess.py:93} INFO - 24/08/20 00:43:14 WARN NativeCodeLoader: Unable to load native-hadoop library for your platform... using builtin-java classes where applicable
[2024-08-20T00:43:15.315+0000] {subprocess.py:93} INFO - Traceback (most recent call last):
[2024-08-20T00:43:15.316+0000] {subprocess.py:93} INFO -   File "/home/***/.local/lib/python3.11/site-packages/urllib3/connection.py", line 174, in _new_conn
[2024-08-20T00:43:15.317+0000] {subprocess.py:93} INFO -     conn = connection.create_connection(
[2024-08-20T00:43:15.318+0000] {subprocess.py:93} INFO -            ^^^^^^^^^^^^^^^^^^^^^^^^^^^^^
[2024-08-20T00:43:15.318+0000] {subprocess.py:93} INFO -   File "/home/***/.local/lib/python3.11/site-packages/urllib3/util/connection.py", line 72, in create_connection
[2024-08-20T00:43:15.318+0000] {subprocess.py:93} INFO -     for res in socket.getaddrinfo(host, port, family, socket.SOCK_STREAM):
[2024-08-20T00:43:15.319+0000] {subprocess.py:93} INFO -                ^^^^^^^^^^^^^^^^^^^^^^^^^^^^^^^^^^^^^^^^^^^^^^^^^^^^^^^^^^
[2024-08-20T00:43:15.319+0000] {subprocess.py:93} INFO -   File "/usr/local/lib/python3.11/socket.py", line 962, in getaddrinfo
[2024-08-20T00:43:15.319+0000] {subprocess.py:93} INFO -     for res in _socket.getaddrinfo(host, port, family, type, proto, flags):
[2024-08-20T00:43:15.319+0000] {subprocess.py:93} INFO -                ^^^^^^^^^^^^^^^^^^^^^^^^^^^^^^^^^^^^^^^^^^^^^^^^^^^^^^^^^^^
[2024-08-20T00:43:15.319+0000] {subprocess.py:93} INFO - socket.gaierror: [Errno -2] Name or service not known
[2024-08-20T00:43:15.319+0000] {subprocess.py:93} INFO - 
[2024-08-20T00:43:15.320+0000] {subprocess.py:93} INFO - During handling of the above exception, another exception occurred:
[2024-08-20T00:43:15.320+0000] {subprocess.py:93} INFO - 
[2024-08-20T00:43:15.320+0000] {subprocess.py:93} INFO - Traceback (most recent call last):
[2024-08-20T00:43:15.320+0000] {subprocess.py:93} INFO -   File "/home/***/.local/lib/python3.11/site-packages/urllib3/connectionpool.py", line 714, in urlopen
[2024-08-20T00:43:15.321+0000] {subprocess.py:93} INFO -     httplib_response = self._make_request(
[2024-08-20T00:43:15.321+0000] {subprocess.py:93} INFO -                        ^^^^^^^^^^^^^^^^^^^
[2024-08-20T00:43:15.321+0000] {subprocess.py:93} INFO -   File "/home/***/.local/lib/python3.11/site-packages/urllib3/connectionpool.py", line 403, in _make_request
[2024-08-20T00:43:15.321+0000] {subprocess.py:93} INFO -     self._validate_conn(conn)
[2024-08-20T00:43:15.321+0000] {subprocess.py:93} INFO -   File "/home/***/.local/lib/python3.11/site-packages/urllib3/connectionpool.py", line 1053, in _validate_conn
[2024-08-20T00:43:15.322+0000] {subprocess.py:93} INFO -     conn.connect()
[2024-08-20T00:43:15.322+0000] {subprocess.py:93} INFO -   File "/home/***/.local/lib/python3.11/site-packages/urllib3/connection.py", line 363, in connect
[2024-08-20T00:43:15.322+0000] {subprocess.py:93} INFO -     self.sock = conn = self._new_conn()
[2024-08-20T00:43:15.322+0000] {subprocess.py:93} INFO -                        ^^^^^^^^^^^^^^^^
[2024-08-20T00:43:15.322+0000] {subprocess.py:93} INFO -   File "/home/***/.local/lib/python3.11/site-packages/urllib3/connection.py", line 186, in _new_conn
[2024-08-20T00:43:15.322+0000] {subprocess.py:93} INFO -     raise NewConnectionError(
[2024-08-20T00:43:15.322+0000] {subprocess.py:93} INFO - urllib3.exceptions.NewConnectionError: <urllib3.connection.HTTPSConnection object at 0xffff87aef6d0>: Failed to establish a new connection: [Errno -2] Name or service not known
[2024-08-20T00:43:15.322+0000] {subprocess.py:93} INFO - 
[2024-08-20T00:43:15.323+0000] {subprocess.py:93} INFO - During handling of the above exception, another exception occurred:
[2024-08-20T00:43:15.323+0000] {subprocess.py:93} INFO - 
[2024-08-20T00:43:15.323+0000] {subprocess.py:93} INFO - Traceback (most recent call last):
[2024-08-20T00:43:15.323+0000] {subprocess.py:93} INFO -   File "/home/***/.local/lib/python3.11/site-packages/requests/adapters.py", line 486, in send
[2024-08-20T00:43:15.323+0000] {subprocess.py:93} INFO -     resp = conn.urlopen(
[2024-08-20T00:43:15.323+0000] {subprocess.py:93} INFO -            ^^^^^^^^^^^^^
[2024-08-20T00:43:15.323+0000] {subprocess.py:93} INFO -   File "/home/***/.local/lib/python3.11/site-packages/urllib3/connectionpool.py", line 798, in urlopen
[2024-08-20T00:43:15.323+0000] {subprocess.py:93} INFO -     retries = retries.increment(
[2024-08-20T00:43:15.323+0000] {subprocess.py:93} INFO -               ^^^^^^^^^^^^^^^^^^
[2024-08-20T00:43:15.324+0000] {subprocess.py:93} INFO -   File "/home/***/.local/lib/python3.11/site-packages/urllib3/util/retry.py", line 592, in increment
[2024-08-20T00:43:15.324+0000] {subprocess.py:93} INFO -     raise MaxRetryError(_pool, url, error or ResponseError(cause))
[2024-08-20T00:43:15.324+0000] {subprocess.py:93} INFO - urllib3.exceptions.MaxRetryError: HTTPSConnectionPool(host='real-time-finance-data.p.rapidapi.com', port=443): Max retries exceeded with url: /market-trends?trend_type=MARKET_INDEXES&country=us&language=en (Caused by NewConnectionError('<urllib3.connection.HTTPSConnection object at 0xffff87aef6d0>: Failed to establish a new connection: [Errno -2] Name or service not known'))
[2024-08-20T00:43:15.324+0000] {subprocess.py:93} INFO - 
[2024-08-20T00:43:15.324+0000] {subprocess.py:93} INFO - During handling of the above exception, another exception occurred:
[2024-08-20T00:43:15.324+0000] {subprocess.py:93} INFO - 
[2024-08-20T00:43:15.324+0000] {subprocess.py:93} INFO - Traceback (most recent call last):
[2024-08-20T00:43:15.324+0000] {subprocess.py:93} INFO -   File "/opt/***/jobs/fetch_data.py", line 35, in <module>
[2024-08-20T00:43:15.325+0000] {subprocess.py:93} INFO -     market_trends = fetch_market_trends()
[2024-08-20T00:43:15.325+0000] {subprocess.py:93} INFO -                     ^^^^^^^^^^^^^^^^^^^^^
[2024-08-20T00:43:15.325+0000] {subprocess.py:93} INFO -   File "/opt/***/jobs/fetch_data.py", line 13, in fetch_market_trends
[2024-08-20T00:43:15.325+0000] {subprocess.py:93} INFO -     response = requests.get(url, headers=headers, params=querystring)
[2024-08-20T00:43:15.325+0000] {subprocess.py:93} INFO -                ^^^^^^^^^^^^^^^^^^^^^^^^^^^^^^^^^^^^^^^^^^^^^^^^^^^^^^
[2024-08-20T00:43:15.325+0000] {subprocess.py:93} INFO -   File "/home/***/.local/lib/python3.11/site-packages/requests/api.py", line 73, in get
[2024-08-20T00:43:15.325+0000] {subprocess.py:93} INFO -     return request("get", url, params=params, **kwargs)
[2024-08-20T00:43:15.325+0000] {subprocess.py:93} INFO -            ^^^^^^^^^^^^^^^^^^^^^^^^^^^^^^^^^^^^^^^^^^^^
[2024-08-20T00:43:15.325+0000] {subprocess.py:93} INFO -   File "/home/***/.local/lib/python3.11/site-packages/requests/api.py", line 59, in request
[2024-08-20T00:43:15.325+0000] {subprocess.py:93} INFO -     return session.request(method=method, url=url, **kwargs)
[2024-08-20T00:43:15.326+0000] {subprocess.py:93} INFO -            ^^^^^^^^^^^^^^^^^^^^^^^^^^^^^^^^^^^^^^^^^^^^^^^^^
[2024-08-20T00:43:15.326+0000] {subprocess.py:93} INFO -   File "/home/***/.local/lib/python3.11/site-packages/requests/sessions.py", line 589, in request
[2024-08-20T00:43:15.326+0000] {subprocess.py:93} INFO -     resp = self.send(prep, **send_kwargs)
[2024-08-20T00:43:15.326+0000] {subprocess.py:93} INFO -            ^^^^^^^^^^^^^^^^^^^^^^^^^^^^^^
[2024-08-20T00:43:15.326+0000] {subprocess.py:93} INFO -   File "/home/***/.local/lib/python3.11/site-packages/requests/sessions.py", line 703, in send
[2024-08-20T00:43:15.327+0000] {subprocess.py:93} INFO -     r = adapter.send(request, **kwargs)
[2024-08-20T00:43:15.327+0000] {subprocess.py:93} INFO -         ^^^^^^^^^^^^^^^^^^^^^^^^^^^^^^^
[2024-08-20T00:43:15.328+0000] {subprocess.py:93} INFO -   File "/home/***/.local/lib/python3.11/site-packages/requests/adapters.py", line 519, in send
[2024-08-20T00:43:15.328+0000] {subprocess.py:93} INFO -     raise ConnectionError(e, request=request)
[2024-08-20T00:43:15.328+0000] {subprocess.py:93} INFO - requests.exceptions.ConnectionError: HTTPSConnectionPool(host='real-time-finance-data.p.rapidapi.com', port=443): Max retries exceeded with url: /market-trends?trend_type=MARKET_INDEXES&country=us&language=en (Caused by NewConnectionError('<urllib3.connection.HTTPSConnection object at 0xffff87aef6d0>: Failed to establish a new connection: [Errno -2] Name or service not known'))
[2024-08-20T00:43:15.342+0000] {subprocess.py:93} INFO - 24/08/20 00:43:15 INFO ShutdownHookManager: Shutdown hook called
[2024-08-20T00:43:15.342+0000] {subprocess.py:93} INFO - 24/08/20 00:43:15 INFO ShutdownHookManager: Deleting directory /tmp/spark-a343e621-2b15-4b19-95d1-6ab1e9fc1c84
[2024-08-20T00:43:15.373+0000] {subprocess.py:97} INFO - Command exited with return code 1
[2024-08-20T00:43:15.388+0000] {taskinstance.py:1935} ERROR - Task failed with exception
Traceback (most recent call last):
  File "/home/airflow/.local/lib/python3.11/site-packages/airflow/operators/bash.py", line 210, in execute
    raise AirflowException(
airflow.exceptions.AirflowException: Bash command failed. The command returned a non-zero exit code 1.
[2024-08-20T00:43:15.391+0000] {taskinstance.py:1398} INFO - Marking task as FAILED. dag_id=data_pipeline_api, task_id=fetch_data, execution_date=20240819T003000, start_date=20240820T004312, end_date=20240820T004315
[2024-08-20T00:43:15.401+0000] {standard_task_runner.py:104} ERROR - Failed to execute job 72 for task fetch_data (Bash command failed. The command returned a non-zero exit code 1.; 77066)
[2024-08-20T00:43:15.447+0000] {local_task_job_runner.py:228} INFO - Task exited with return code 1
[2024-08-20T00:43:15.488+0000] {taskinstance.py:2776} INFO - 0 downstream tasks scheduled from follow-on schedule check
