[2024-07-30T00:43:07.124+0000] {taskinstance.py:1157} INFO - Dependencies all met for dep_context=non-requeueable deps ti=<TaskInstance: data_pipeline.process_data scheduled__2024-07-29T00:30:00+00:00 [queued]>
[2024-07-30T00:43:07.127+0000] {taskinstance.py:1157} INFO - Dependencies all met for dep_context=requeueable deps ti=<TaskInstance: data_pipeline.process_data scheduled__2024-07-29T00:30:00+00:00 [queued]>
[2024-07-30T00:43:07.128+0000] {taskinstance.py:1359} INFO - Starting attempt 1 of 2
[2024-07-30T00:43:07.132+0000] {taskinstance.py:1380} INFO - Executing <Task(BashOperator): process_data> on 2024-07-29 00:30:00+00:00
[2024-07-30T00:43:07.135+0000] {standard_task_runner.py:57} INFO - Started process 51713 to run task
[2024-07-30T00:43:07.136+0000] {standard_task_runner.py:84} INFO - Running: ['***', 'tasks', 'run', 'data_pipeline', 'process_data', 'scheduled__2024-07-29T00:30:00+00:00', '--job-id', '71', '--raw', '--subdir', 'DAGS_FOLDER/spark-jobs.py', '--cfg-path', '/tmp/tmpqb0h0118']
[2024-07-30T00:43:07.137+0000] {standard_task_runner.py:85} INFO - Job 71: Subtask process_data
[2024-07-30T00:43:07.157+0000] {task_command.py:415} INFO - Running <TaskInstance: data_pipeline.process_data scheduled__2024-07-29T00:30:00+00:00 [running]> on host c553c98b8e80
[2024-07-30T00:43:07.182+0000] {taskinstance.py:1660} INFO - Exporting env vars: AIRFLOW_CTX_DAG_OWNER='***' AIRFLOW_CTX_DAG_ID='data_pipeline' AIRFLOW_CTX_TASK_ID='process_data' AIRFLOW_CTX_EXECUTION_DATE='2024-07-29T00:30:00+00:00' AIRFLOW_CTX_TRY_NUMBER='1' AIRFLOW_CTX_DAG_RUN_ID='scheduled__2024-07-29T00:30:00+00:00'
[2024-07-30T00:43:07.183+0000] {subprocess.py:63} INFO - Tmp dir root location: /tmp
[2024-07-30T00:43:07.183+0000] {subprocess.py:75} INFO - Running command: ['/bin/bash', '-c', 'python /opt/***/jobs/process_data.py ']
[2024-07-30T00:43:07.187+0000] {subprocess.py:86} INFO - Output:
[2024-07-30T00:43:07.219+0000] {subprocess.py:93} INFO - python: can't open file '/opt/***/jobs/process_data.py': [Errno 2] No such file or directory
[2024-07-30T00:43:07.221+0000] {subprocess.py:97} INFO - Command exited with return code 2
[2024-07-30T00:43:07.226+0000] {taskinstance.py:1935} ERROR - Task failed with exception
Traceback (most recent call last):
  File "/home/airflow/.local/lib/python3.11/site-packages/airflow/operators/bash.py", line 210, in execute
    raise AirflowException(
airflow.exceptions.AirflowException: Bash command failed. The command returned a non-zero exit code 2.
[2024-07-30T00:43:07.227+0000] {taskinstance.py:1398} INFO - Marking task as UP_FOR_RETRY. dag_id=data_pipeline, task_id=process_data, execution_date=20240729T003000, start_date=20240730T004307, end_date=20240730T004307
[2024-07-30T00:43:07.232+0000] {standard_task_runner.py:104} ERROR - Failed to execute job 71 for task process_data (Bash command failed. The command returned a non-zero exit code 2.; 51713)
[2024-07-30T00:43:07.238+0000] {local_task_job_runner.py:228} INFO - Task exited with return code 1
[2024-07-30T00:43:07.250+0000] {taskinstance.py:2776} INFO - 0 downstream tasks scheduled from follow-on schedule check
