[2024-08-11T00:33:38.117+0000] {taskinstance.py:1157} INFO - Dependencies all met for dep_context=non-requeueable deps ti=<TaskInstance: data_pipeline_api.fetch_data scheduled__2024-08-10T00:30:00+00:00 [queued]>
[2024-08-11T00:33:38.121+0000] {taskinstance.py:1157} INFO - Dependencies all met for dep_context=requeueable deps ti=<TaskInstance: data_pipeline_api.fetch_data scheduled__2024-08-10T00:30:00+00:00 [queued]>
[2024-08-11T00:33:38.121+0000] {taskinstance.py:1359} INFO - Starting attempt 1 of 2
[2024-08-11T00:33:38.126+0000] {taskinstance.py:1380} INFO - Executing <Task(BashOperator): fetch_data> on 2024-08-10 00:30:00+00:00
[2024-08-11T00:33:38.129+0000] {standard_task_runner.py:57} INFO - Started process 31825 to run task
[2024-08-11T00:33:38.131+0000] {standard_task_runner.py:84} INFO - Running: ['***', 'tasks', 'run', 'data_pipeline_api', 'fetch_data', 'scheduled__2024-08-10T00:30:00+00:00', '--job-id', '27', '--raw', '--subdir', 'DAGS_FOLDER/spark-jobs.py', '--cfg-path', '/tmp/tmpziz4f3vq']
[2024-08-11T00:33:38.132+0000] {standard_task_runner.py:85} INFO - Job 27: Subtask fetch_data
[2024-08-11T00:33:38.154+0000] {task_command.py:415} INFO - Running <TaskInstance: data_pipeline_api.fetch_data scheduled__2024-08-10T00:30:00+00:00 [running]> on host 27ef58cc88fc
[2024-08-11T00:33:38.189+0000] {taskinstance.py:1660} INFO - Exporting env vars: AIRFLOW_CTX_DAG_OWNER='***' AIRFLOW_CTX_DAG_ID='data_pipeline_api' AIRFLOW_CTX_TASK_ID='fetch_data' AIRFLOW_CTX_EXECUTION_DATE='2024-08-10T00:30:00+00:00' AIRFLOW_CTX_TRY_NUMBER='1' AIRFLOW_CTX_DAG_RUN_ID='scheduled__2024-08-10T00:30:00+00:00'
[2024-08-11T00:33:38.190+0000] {subprocess.py:63} INFO - Tmp dir root location: /tmp
[2024-08-11T00:33:38.190+0000] {subprocess.py:75} INFO - Running command: ['/bin/bash', '-c', 'bash /opt/***/jobs/spark-submit.sh /opt/***/jobs/fetch_data.py ']
[2024-08-11T00:33:38.196+0000] {subprocess.py:86} INFO - Output:
[2024-08-11T00:33:38.207+0000] {subprocess.py:93} INFO - /opt/***/jobs/fetch_data.py
[2024-08-11T00:33:38.289+0000] {subprocess.py:93} INFO - /home/***/.local/lib/python3.11/site-packages/pyspark/bin/load-spark-env.sh: line 68: ps: command not found
[2024-08-11T00:33:39.651+0000] {subprocess.py:93} INFO - 24/08/11 00:33:39 WARN NativeCodeLoader: Unable to load native-hadoop library for your platform... using builtin-java classes where applicable
[2024-08-11T00:33:40.042+0000] {subprocess.py:93} INFO - Traceback (most recent call last):
[2024-08-11T00:33:40.050+0000] {subprocess.py:93} INFO -   File "/home/***/.local/lib/python3.11/site-packages/urllib3/connection.py", line 174, in _new_conn
[2024-08-11T00:33:40.051+0000] {subprocess.py:93} INFO -     conn = connection.create_connection(
[2024-08-11T00:33:40.051+0000] {subprocess.py:93} INFO -            ^^^^^^^^^^^^^^^^^^^^^^^^^^^^^
[2024-08-11T00:33:40.051+0000] {subprocess.py:93} INFO -   File "/home/***/.local/lib/python3.11/site-packages/urllib3/util/connection.py", line 72, in create_connection
[2024-08-11T00:33:40.051+0000] {subprocess.py:93} INFO -     for res in socket.getaddrinfo(host, port, family, socket.SOCK_STREAM):
[2024-08-11T00:33:40.052+0000] {subprocess.py:93} INFO -                ^^^^^^^^^^^^^^^^^^^^^^^^^^^^^^^^^^^^^^^^^^^^^^^^^^^^^^^^^^
[2024-08-11T00:33:40.052+0000] {subprocess.py:93} INFO -   File "/usr/local/lib/python3.11/socket.py", line 962, in getaddrinfo
[2024-08-11T00:33:40.052+0000] {subprocess.py:93} INFO -     for res in _socket.getaddrinfo(host, port, family, type, proto, flags):
[2024-08-11T00:33:40.052+0000] {subprocess.py:93} INFO -                ^^^^^^^^^^^^^^^^^^^^^^^^^^^^^^^^^^^^^^^^^^^^^^^^^^^^^^^^^^^
[2024-08-11T00:33:40.052+0000] {subprocess.py:93} INFO - socket.gaierror: [Errno -2] Name or service not known
[2024-08-11T00:33:40.053+0000] {subprocess.py:93} INFO - 
[2024-08-11T00:33:40.053+0000] {subprocess.py:93} INFO - During handling of the above exception, another exception occurred:
[2024-08-11T00:33:40.059+0000] {subprocess.py:93} INFO - 
[2024-08-11T00:33:40.060+0000] {subprocess.py:93} INFO - Traceback (most recent call last):
[2024-08-11T00:33:40.060+0000] {subprocess.py:93} INFO -   File "/home/***/.local/lib/python3.11/site-packages/urllib3/connectionpool.py", line 714, in urlopen
[2024-08-11T00:33:40.062+0000] {subprocess.py:93} INFO -     httplib_response = self._make_request(
[2024-08-11T00:33:40.062+0000] {subprocess.py:93} INFO -                        ^^^^^^^^^^^^^^^^^^^
[2024-08-11T00:33:40.062+0000] {subprocess.py:93} INFO -   File "/home/***/.local/lib/python3.11/site-packages/urllib3/connectionpool.py", line 403, in _make_request
[2024-08-11T00:33:40.062+0000] {subprocess.py:93} INFO -     self._validate_conn(conn)
[2024-08-11T00:33:40.063+0000] {subprocess.py:93} INFO -   File "/home/***/.local/lib/python3.11/site-packages/urllib3/connectionpool.py", line 1053, in _validate_conn
[2024-08-11T00:33:40.063+0000] {subprocess.py:93} INFO -     conn.connect()
[2024-08-11T00:33:40.063+0000] {subprocess.py:93} INFO -   File "/home/***/.local/lib/python3.11/site-packages/urllib3/connection.py", line 363, in connect
[2024-08-11T00:33:40.063+0000] {subprocess.py:93} INFO -     self.sock = conn = self._new_conn()
[2024-08-11T00:33:40.063+0000] {subprocess.py:93} INFO -                        ^^^^^^^^^^^^^^^^
[2024-08-11T00:33:40.064+0000] {subprocess.py:93} INFO -   File "/home/***/.local/lib/python3.11/site-packages/urllib3/connection.py", line 186, in _new_conn
[2024-08-11T00:33:40.068+0000] {subprocess.py:93} INFO -     raise NewConnectionError(
[2024-08-11T00:33:40.068+0000] {subprocess.py:93} INFO - urllib3.exceptions.NewConnectionError: <urllib3.connection.HTTPSConnection object at 0xffff8235f590>: Failed to establish a new connection: [Errno -2] Name or service not known
[2024-08-11T00:33:40.069+0000] {subprocess.py:93} INFO - 
[2024-08-11T00:33:40.069+0000] {subprocess.py:93} INFO - During handling of the above exception, another exception occurred:
[2024-08-11T00:33:40.069+0000] {subprocess.py:93} INFO - 
[2024-08-11T00:33:40.069+0000] {subprocess.py:93} INFO - Traceback (most recent call last):
[2024-08-11T00:33:40.069+0000] {subprocess.py:93} INFO -   File "/home/***/.local/lib/python3.11/site-packages/requests/adapters.py", line 486, in send
[2024-08-11T00:33:40.069+0000] {subprocess.py:93} INFO -     resp = conn.urlopen(
[2024-08-11T00:33:40.069+0000] {subprocess.py:93} INFO -            ^^^^^^^^^^^^^
[2024-08-11T00:33:40.070+0000] {subprocess.py:93} INFO -   File "/home/***/.local/lib/python3.11/site-packages/urllib3/connectionpool.py", line 798, in urlopen
[2024-08-11T00:33:40.070+0000] {subprocess.py:93} INFO -     retries = retries.increment(
[2024-08-11T00:33:40.070+0000] {subprocess.py:93} INFO -               ^^^^^^^^^^^^^^^^^^
[2024-08-11T00:33:40.070+0000] {subprocess.py:93} INFO -   File "/home/***/.local/lib/python3.11/site-packages/urllib3/util/retry.py", line 592, in increment
[2024-08-11T00:33:40.070+0000] {subprocess.py:93} INFO -     raise MaxRetryError(_pool, url, error or ResponseError(cause))
[2024-08-11T00:33:40.070+0000] {subprocess.py:93} INFO - urllib3.exceptions.MaxRetryError: HTTPSConnectionPool(host='real-time-finance-data.p.rapidapi.com', port=443): Max retries exceeded with url: /market-trends?trend_type=MARKET_INDEXES&country=us&language=en (Caused by NewConnectionError('<urllib3.connection.HTTPSConnection object at 0xffff8235f590>: Failed to establish a new connection: [Errno -2] Name or service not known'))
[2024-08-11T00:33:40.070+0000] {subprocess.py:93} INFO - 
[2024-08-11T00:33:40.070+0000] {subprocess.py:93} INFO - During handling of the above exception, another exception occurred:
[2024-08-11T00:33:40.071+0000] {subprocess.py:93} INFO - 
[2024-08-11T00:33:40.071+0000] {subprocess.py:93} INFO - Traceback (most recent call last):
[2024-08-11T00:33:40.071+0000] {subprocess.py:93} INFO -   File "/opt/***/jobs/fetch_data.py", line 35, in <module>
[2024-08-11T00:33:40.071+0000] {subprocess.py:93} INFO -     market_trends = fetch_market_trends()
[2024-08-11T00:33:40.072+0000] {subprocess.py:93} INFO -                     ^^^^^^^^^^^^^^^^^^^^^
[2024-08-11T00:33:40.072+0000] {subprocess.py:93} INFO -   File "/opt/***/jobs/fetch_data.py", line 13, in fetch_market_trends
[2024-08-11T00:33:40.074+0000] {subprocess.py:93} INFO -     response = requests.get(url, headers=headers, params=querystring)
[2024-08-11T00:33:40.077+0000] {subprocess.py:93} INFO -                ^^^^^^^^^^^^^^^^^^^^^^^^^^^^^^^^^^^^^^^^^^^^^^^^^^^^^^
[2024-08-11T00:33:40.077+0000] {subprocess.py:93} INFO -   File "/home/***/.local/lib/python3.11/site-packages/requests/api.py", line 73, in get
[2024-08-11T00:33:40.078+0000] {subprocess.py:93} INFO -     return request("get", url, params=params, **kwargs)
[2024-08-11T00:33:40.078+0000] {subprocess.py:93} INFO -            ^^^^^^^^^^^^^^^^^^^^^^^^^^^^^^^^^^^^^^^^^^^^
[2024-08-11T00:33:40.078+0000] {subprocess.py:93} INFO -   File "/home/***/.local/lib/python3.11/site-packages/requests/api.py", line 59, in request
[2024-08-11T00:33:40.078+0000] {subprocess.py:93} INFO -     return session.request(method=method, url=url, **kwargs)
[2024-08-11T00:33:40.078+0000] {subprocess.py:93} INFO -            ^^^^^^^^^^^^^^^^^^^^^^^^^^^^^^^^^^^^^^^^^^^^^^^^^
[2024-08-11T00:33:40.078+0000] {subprocess.py:93} INFO -   File "/home/***/.local/lib/python3.11/site-packages/requests/sessions.py", line 589, in request
[2024-08-11T00:33:40.078+0000] {subprocess.py:93} INFO -     resp = self.send(prep, **send_kwargs)
[2024-08-11T00:33:40.078+0000] {subprocess.py:93} INFO -            ^^^^^^^^^^^^^^^^^^^^^^^^^^^^^^
[2024-08-11T00:33:40.078+0000] {subprocess.py:93} INFO -   File "/home/***/.local/lib/python3.11/site-packages/requests/sessions.py", line 703, in send
[2024-08-11T00:33:40.079+0000] {subprocess.py:93} INFO -     r = adapter.send(request, **kwargs)
[2024-08-11T00:33:40.079+0000] {subprocess.py:93} INFO -         ^^^^^^^^^^^^^^^^^^^^^^^^^^^^^^^
[2024-08-11T00:33:40.079+0000] {subprocess.py:93} INFO -   File "/home/***/.local/lib/python3.11/site-packages/requests/adapters.py", line 519, in send
[2024-08-11T00:33:40.079+0000] {subprocess.py:93} INFO -     raise ConnectionError(e, request=request)
[2024-08-11T00:33:40.079+0000] {subprocess.py:93} INFO - requests.exceptions.ConnectionError: HTTPSConnectionPool(host='real-time-finance-data.p.rapidapi.com', port=443): Max retries exceeded with url: /market-trends?trend_type=MARKET_INDEXES&country=us&language=en (Caused by NewConnectionError('<urllib3.connection.HTTPSConnection object at 0xffff8235f590>: Failed to establish a new connection: [Errno -2] Name or service not known'))
[2024-08-11T00:33:40.101+0000] {subprocess.py:93} INFO - 24/08/11 00:33:40 INFO ShutdownHookManager: Shutdown hook called
[2024-08-11T00:33:40.102+0000] {subprocess.py:93} INFO - 24/08/11 00:33:40 INFO ShutdownHookManager: Deleting directory /tmp/spark-4d87cde4-22d0-4f02-b1a9-8e1217f12fd5
[2024-08-11T00:33:40.128+0000] {subprocess.py:97} INFO - Command exited with return code 1
[2024-08-11T00:33:40.136+0000] {taskinstance.py:1935} ERROR - Task failed with exception
Traceback (most recent call last):
  File "/home/airflow/.local/lib/python3.11/site-packages/airflow/operators/bash.py", line 210, in execute
    raise AirflowException(
airflow.exceptions.AirflowException: Bash command failed. The command returned a non-zero exit code 1.
[2024-08-11T00:33:40.139+0000] {taskinstance.py:1398} INFO - Marking task as UP_FOR_RETRY. dag_id=data_pipeline_api, task_id=fetch_data, execution_date=20240810T003000, start_date=20240811T003338, end_date=20240811T003340
[2024-08-11T00:33:40.146+0000] {standard_task_runner.py:104} ERROR - Failed to execute job 27 for task fetch_data (Bash command failed. The command returned a non-zero exit code 1.; 31825)
[2024-08-11T00:33:40.177+0000] {local_task_job_runner.py:228} INFO - Task exited with return code 1
[2024-08-11T00:33:40.187+0000] {taskinstance.py:2776} INFO - 0 downstream tasks scheduled from follow-on schedule check
